Workbook
Name Criterio1: 'Empresas y UTE'!$AG$1:$AG$35
Name Criterio2: 'Empresas y UTE'!$AF$1:$AF$81
Name CriterioGrupo: 'Empresas y UTE'!$BW$1:$BW$68

Sheet Consulta de contratos
A1: CONSULTA DE CONTRATOS MUNICIPALES | K1: =IF(OR(B4="",B4="Sin filtro"),"",B4)
A2: Seleccione uno o varios criterios. Para retirar un criterio, elija «Sin filtro» en su lista. | K2: =IF(OR(B8="",B8="Sin filtro"),"",B8)
K3: =IF(OR(B10="",B10="Sin filtro"),"",B10)
A4: Distrito | B4: Sin filtro | E4: ▾ | K4: =IF(OR(B12="",B12="Sin filtro"),"",B12)
K5: =IF(OR(B14="",B14="Sin filtro"),"",B14)
A6: Grupo empresarial | B6: Sin filtro | E6: ▾ | K6: =IF(OR(B6="",B6="Sin filtro"),"",B6)
A8: Empresa / UTE | B8: Sin filtro | E8: ▾
A10: Área de Gobierno | B10: Sin filtro | E10: ▾
A12: Dirección General | B12: Sin filtro | E12: ▾
A14: Subdirección General | B14: Sin filtro | E14: ▾
A16: =IF(AND(K3<>"",K4<>"",COUNTIFS(Datos!$C$2:$C$1000,K3,Datos!$D$2:$D$1000,K4)=0),"Revise filtros: Área y Dirección General no son compatibles",IF(AND(K4<>"",K5<>"",COUNTIFS(Datos!$D$2:$D$1000,K4,Datos!$E$2:$E$1000,K5)=0),"Revise filtros: Dirección y Subdirección no son compatibles",IF(SUM(IF(K1="",0,1),IF(K2="",0,1),IF(K3="",0,1),IF(K4="",0,1),IF(K5="",0,1),IF(K6="",0,1))=0,"Seleccione un criterio para iniciar la consulta",IF(SUM(Datos!V2:V1000)=0,"Sin coincidencias. Retire o cambie un criterio.",SUM(Datos!V2:V1000)&" prestaciones encontradas")))) -> Seleccione un criterio para iniciar la consulta
A17: Distrito | B17: Subdirección General | C17: Empresa / UTE | D17: Denominación del contrato | E17: Lote | F17: Titular de la Dirección General | G17: Fin de vigencia registrado | H17: Prestación y particularidades
A18: =IF($J18=0,"",IF(INDEX(Datos!$A$2:$A$1000,$J18)="","",INDEX(Datos!$A$2:$A$1000,$J18))) | B18: =IF($J18=0,"",IF(INDEX(Datos!$E$2:$E$1000,$J18)="","",INDEX(Datos!$E$2:$E$1000,$J18))) | C18: =IF($J18=0,"",IF(INDEX(Datos!$I$2:$I$1000,$J18)="","",INDEX(Datos!$I$2:$I$1000,$J18))) | D18: =IF($J18=0,"",IF(INDEX(Datos!$F$2:$F$1000,$J18)="","",INDEX(Datos!$F$2:$F$1000,$J18))) | E18: =IF($J18=0,"",IF(INDEX(Datos!$H$2:$H$1000,$J18)="","",INDEX(Datos!$H$2:$H$1000,$J18))) | F18: =IF($J18=0,"",IF(INDEX(Datos!$N$2:$N$1000,$J18)="","",INDEX(Datos!$N$2:$N$1000,$J18))) | G18: =IF($J18=0,"",IF(INDEX(Datos!$M$2:$M$1000,$J18)="","",INDEX(Datos!$M$2:$M$1000,$J18))) | H18: =IF($J18=0,"",INDEX(Datos!$J$2:$J$1000,$J18)&IF(INDEX(Datos!$Q$2:$Q$1000,$J18)="",""," | "&INDEX(Datos!$Q$2:$Q$1000,$J18))) | J18: =IFERROR(MATCH(ROW()-17,Datos!$W$2:$W$1000,0),0) -> 0
A19: =IF($J19=0,"",IF(INDEX(Datos!$A$2:$A$1000,$J19)="","",INDEX(Datos!$A$2:$A$1000,$J19))) | B19: =IF($J19=0,"",IF(INDEX(Datos!$E$2:$E$1000,$J19)="","",INDEX(Datos!$E$2:$E$1000,$J19))) | C19: =IF($J19=0,"",IF(INDEX(Datos!$I$2:$I$1000,$J19)="","",INDEX(Datos!$I$2:$I$1000,$J19))) | D19: =IF($J19=0,"",IF(INDEX(Datos!$F$2:$F$1000,$J19)="","",INDEX(Datos!$F$2:$F$1000,$J19))) | E19: =IF($J19=0,"",IF(INDEX(Datos!$H$2:$H$1000,$J19)="","",INDEX(Datos!$H$2:$H$1000,$J19))) | F19: =IF($J19=0,"",IF(INDEX(Datos!$N$2:$N$1000,$J19)="","",INDEX(Datos!$N$2:$N$1000,$J19))) | G19: =IF($J19=0,"",IF(INDEX(Datos!$M$2:$M$1000,$J19)="","",INDEX(Datos!$M$2:$M$1000,$J19))) | H19: =IF($J19=0,"",INDEX(Datos!$J$2:$J$1000,$J19)&IF(INDEX(Datos!$Q$2:$Q$1000,$J19)="",""," | "&INDEX(Datos!$Q$2:$Q$1000,$J19))) | J19: =IFERROR(MATCH(ROW()-17,Datos!$W$2:$W$1000,0),0) -> 0
A20: =IF($J20=0,"",IF(INDEX(Datos!$A$2:$A$1000,$J20)="","",INDEX(Datos!$A$2:$A$1000,$J20))) | B20: =IF($J20=0,"",IF(INDEX(Datos!$E$2:$E$1000,$J20)="","",INDEX(Datos!$E$2:$E$1000,$J20))) | C20: =IF($J20=0,"",IF(INDEX(Datos!$I$2:$I$1000,$J20)="","",INDEX(Datos!$I$2:$I$1000,$J20))) | D20: =IF($J20=0,"",IF(INDEX(Datos!$F$2:$F$1000,$J20)="","",INDEX(Datos!$F$2:$F$1000,$J20))) | E20: =IF($J20=0,"",IF(INDEX(Datos!$H$2:$H$1000,$J20)="","",INDEX(Datos!$H$2:$H$1000,$J20))) | F20: =IF($J20=0,"",IF(INDEX(Datos!$N$2:$N$1000,$J20)="","",INDEX(Datos!$N$2:$N$1000,$J20))) | G20: =IF($J20=0,"",IF(INDEX(Datos!$M$2:$M$1000,$J20)="","",INDEX(Datos!$M$2:$M$1000,$J20))) | H20: =IF($J20=0,"",INDEX(Datos!$J$2:$J$1000,$J20)&IF(INDEX(Datos!$Q$2:$Q$1000,$J20)="",""," | "&INDEX(Datos!$Q$2:$Q$1000,$J20))) | J20: =IFERROR(MATCH(ROW()-17,Datos!$W$2:$W$1000,0),0) -> 0
A21: =IF($J21=0,"",IF(INDEX(Datos!$A$2:$A$1000,$J21)="","",INDEX(Datos!$A$2:$A$1000,$J21))) | B21: =IF($J21=0,"",IF(INDEX(Datos!$E$2:$E$1000,$J21)="","",INDEX(Datos!$E$2:$E$1000,$J21))) | C21: =IF($J21=0,"",IF(INDEX(Datos!$I$2:$I$1000,$J21)="","",INDEX(Datos!$I$2:$I$1000,$J21))) | D21: =IF($J21=0,"",IF(INDEX(Datos!$F$2:$F$1000,$J21)="","",INDEX(Datos!$F$2:$F$1000,$J21))) | E21: =IF($J21=0,"",IF(INDEX(Datos!$H$2:$H$1000,$J21)="","",INDEX(Datos!$H$2:$H$1000,$J21))) | F21: =IF($J21=0,"",IF(INDEX(Datos!$N$2:$N$1000,$J21)="","",INDEX(Datos!$N$2:$N$1000,$J21))) | G21: =IF($J21=0,"",IF(INDEX(Datos!$M$2:$M$1000,$J21)="","",INDEX(Datos!$M$2:$M$1000,$J21))) | H21: =IF($J21=0,"",INDEX(Datos!$J$2:$J$1000,$J21)&IF(INDEX(Datos!$Q$2:$Q$1000,$J21)="",""," | "&INDEX(Datos!$Q$2:$Q$1000,$J21))) | J21: =IFERROR(MATCH(ROW()-17,Datos!$W$2:$W$1000,0),0) -> 0
A22: =IF($J22=0,"",IF(INDEX(Datos!$A$2:$A$1000,$J22)="","",INDEX(Datos!$A$2:$A$1000,$J22))) | B22: =IF($J22=0,"",IF(INDEX(Datos!$E$2:$E$1000,$J22)="","",INDEX(Datos!$E$2:$E$1000,$J22))) | C22: =IF($J22=0,"",IF(INDEX(Datos!$I$2:$I$1000,$J22)="","",INDEX(Datos!$I$2:$I$1000,$J22))) | D22: =IF($J22=0,"",IF(INDEX(Datos!$F$2:$F$1000,$J22)="","",INDEX(Datos!$F$2:$F$1000,$J22))) | E22: =IF($J22=0,"",IF(INDEX(Datos!$H$2:$H$1000,$J22)="","",INDEX(Datos!$H$2:$H$1000,$J22))) | F22: =IF($J22=0,"",IF(INDEX(Datos!$N$2:$N$1000,$J22)="","",INDEX(Datos!$N$2:$N$1000,$J22))) | G22: =IF($J22=0,"",IF(INDEX(Datos!$M$2:$M$1000,$J22)="","",INDEX(Datos!$M$2:$M$1000,$J22))) | H22: =IF($J22=0,"",INDEX(Datos!$J$2:$J$1000,$J22)&IF(INDEX(Datos!$Q$2:$Q$1000,$J22)="",""," | "&INDEX(Datos!$Q$2:$Q$1000,$J22))) | J22: =IFERROR(MATCH(ROW()-17,Datos!$W$2:$W$1000,0),0) -> 0
A23: =IF($J23=0,"",IF(INDEX(Datos!$A$2:$A$1000,$J23)="","",INDEX(Datos!$A$2:$A$1000,$J23))) | B23: =IF($J23=0,"",IF(INDEX(Datos!$E$2:$E$1000,$J23)="","",INDEX(Datos!$E$2:$E$1000,$J23))) | C23: =IF($J23=0,"",IF(INDEX(Datos!$I$2:$I$1000,$J23)="","",INDEX(Datos!$I$2:$I$1000,$J23))) | D23: =IF($J23=0,"",IF(INDEX(Datos!$F$2:$F$1000,$J23)="","",INDEX(Datos!$F$2:$F$1000,$J23))) | E23: =IF($J23=0,"",IF(INDEX(Datos!$H$2:$H$1000,$J23)="","",INDEX(Datos!$H$2:$H$1000,$J23))) | F23: =IF($J23=0,"",IF(INDEX(Datos!$N$2:$N$1000,$J23)="","",INDEX(Datos!$N$2:$N$1000,$J23))) | G23: =IF($J23=0,"",IF(INDEX(Datos!$M$2:$M$1000,$J23)="","",INDEX(Datos!$M$2:$M$1000,$J23))) | H23: =IF($J23=0,"",INDEX(Datos!$J$2:$J$1000,$J23)&IF(INDEX(Datos!$Q$2:$Q$1000,$J23)="",""," | "&INDEX(Datos!$Q$2:$Q$1000,$J23))) | J23: =IFERROR(MATCH(ROW()-17,Datos!$W$2:$W$1000,0),0) -> 0
A24: =IF($J24=0,"",IF(INDEX(Datos!$A$2:$A$1000,$J24)="","",INDEX(Datos!$A$2:$A$1000,$J24))) | B24: =IF($J24=0,"",IF(INDEX(Datos!$E$2:$E$1000,$J24)="","",INDEX(Datos!$E$2:$E$1000,$J24))) | C24: =IF($J24=0,"",IF(INDEX(Datos!$I$2:$I$1000,$J24)="","",INDEX(Datos!$I$2:$I$1000,$J24))) | D24: =IF($J24=0,"",IF(INDEX(Datos!$F$2:$F$1000,$J24)="","",INDEX(Datos!$F$2:$F$1000,$J24))) | E24: =IF($J24=0,"",IF(INDEX(Datos!$H$2:$H$1000,$J24)="","",INDEX(Datos!$H$2:$H$1000,$J24))) | F24: =IF($J24=0,"",IF(INDEX(Datos!$N$2:$N$1000,$J24)="","",INDEX(Datos!$N$2:$N$1000,$J24))) | G24: =IF($J24=0,"",IF(INDEX(Datos!$M$2:$M$1000,$J24)="","",INDEX(Datos!$M$2:$M$1000,$J24))) | H24: =IF($J24=0,"",INDEX(Datos!$J$2:$J$1000,$J24)&IF(INDEX(Datos!$Q$2:$Q$1000,$J24)="",""," | "&INDEX(Datos!$Q$2:$Q$1000,$J24))) | J24: =IFERROR(MATCH(ROW()-17,Datos!$W$2:$W$1000,0),0) -> 0
A25: =IF($J25=0,"",IF(INDEX(Datos!$A$2:$A$1000,$J25)="","",INDEX(Datos!$A$2:$A$1000,$J25))) | B25: =IF($J25=0,"",IF(INDEX(Datos!$E$2:$E$1000,$J25)="","",INDEX(Datos!$E$2:$E$1000,$J25))) | C25: =IF($J25=0,"",IF(INDEX(Datos!$I$2:$I$1000,$J25)="","",INDEX(Datos!$I$2:$I$1000,$J25))) | D25: =IF($J25=0,"",IF(INDEX(Datos!$F$2:$F$1000,$J25)="","",INDEX(Datos!$F$2:$F$1000,$J25))) | E25: =IF($J25=0,"",IF(INDEX(Datos!$H$2:$H$1000,$J25)="","",INDEX(Datos!$H$2:$H$1000,$J25))) | F25: =IF($J25=0,"",IF(INDEX(Datos!$N$2:$N$1000,$J25)="","",INDEX(Datos!$N$2:$N$1000,$J25))) | G25: =IF($J25=0,"",IF(INDEX(Datos!$M$2:$M$1000,$J25)="","",INDEX(Datos!$M$2:$M$1000,$J25))) | H25: =IF($J25=0,"",INDEX(Datos!$J$2:$J$1000,$J25)&IF(INDEX(Datos!$Q$2:$Q$1000,$J25)="",""," | "&INDEX(Datos!$Q$2:$Q$1000,$J25))) | J25: =IFERROR(MATCH(ROW()-17,Datos!$W$2:$W$1000,0),0) -> 0
A26: =IF($J26=0,"",IF(INDEX(Datos!$A$2:$A$1000,$J26)="","",INDEX(Datos!$A$2:$A$1000,$J26))) | B26: =IF($J26=0,"",IF(INDEX(Datos!$E$2:$E$1000,$J26)="","",INDEX(Datos!$E$2:$E$1000,$J26))) | C26: =IF($J26=0,"",IF(INDEX(Datos!$I$2:$I$1000,$J26)="","",INDEX(Datos!$I$2:$I$1000,$J26))) | D26: =IF($J26=0,"",IF(INDEX(Datos!$F$2:$F$1000,$J26)="","",INDEX(Datos!$F$2:$F$1000,$J26))) | E26: =IF($J26=0,"",IF(INDEX(Datos!$H$2:$H$1000,$J26)="","",INDEX(Datos!$H$2:$H$1000,$J26))) | F26: =IF($J26=0,"",IF(INDEX(Datos!$N$2:$N$1000,$J26)="","",INDEX(Datos!$N$2:$N$1000,$J26))) | G26: =IF($J26=0,"",IF(INDEX(Datos!$M$2:$M$1000,$J26)="","",INDEX(Datos!$M$2:$M$1000,$J26))) | H26: =IF($J26=0,"",INDEX(Datos!$J$2:$J$1000,$J26)&IF(INDEX(Datos!$Q$2:$Q$1000,$J26)="",""," | "&INDEX(Datos!$Q$2:$Q$1000,$J26))) | J26: =IFERROR(MATCH(ROW()-17,Datos!$W$2:$W$1000,0),0) -> 0
A27: =IF($J27=0,"",IF(INDEX(Datos!$A$2:$A$1000,$J27)="","",INDEX(Datos!$A$2:$A$1000,$J27))) | B27: =IF($J27=0,"",IF(INDEX(Datos!$E$2:$E$1000,$J27)="","",INDEX(Datos!$E$2:$E$1000,$J27))) | C27: =IF($J27=0,"",IF(INDEX(Datos!$I$2:$I$1000,$J27)="","",INDEX(Datos!$I$2:$I$1000,$J27))) | D27: =IF($J27=0,"",IF(INDEX(Datos!$F$2:$F$1000,$J27)="","",INDEX(Datos!$F$2:$F$1000,$J27))) | E27: =IF($J27=0,"",IF(INDEX(Datos!$H$2:$H$1000,$J27)="","",INDEX(Datos!$H$2:$H$1000,$J27))) | F27: =IF($J27=0,"",IF(INDEX(Datos!$N$2:$N$1000,$J27)="","",INDEX(Datos!$N$2:$N$1000,$J27))) | G27: =IF($J27=0,"",IF(INDEX(Datos!$M$2:$M$1000,$J27)="","",INDEX(Datos!$M$2:$M$1000,$J27))) | H27: =IF($J27=0,"",INDEX(Datos!$J$2:$J$1000,$J27)&IF(INDEX(Datos!$Q$2:$Q$1000,$J27)="",""," | "&INDEX(Datos!$Q$2:$Q$1000,$J27))) | J27: =IFERROR(MATCH(ROW()-17,Datos!$W$2:$W$1000,0),0) -> 0
A28: =IF($J28=0,"",IF(INDEX(Datos!$A$2:$A$1000,$J28)="","",INDEX(Datos!$A$2:$A$1000,$J28))) | B28: =IF($J28=0,"",IF(INDEX(Datos!$E$2:$E$1000,$J28)="","",INDEX(Datos!$E$2:$E$1000,$J28))) | C28: =IF($J28=0,"",IF(INDEX(Datos!$I$2:$I$1000,$J28)="","",INDEX(Datos!$I$2:$I$1000,$J28))) | D28: =IF($J28=0,"",IF(INDEX(Datos!$F$2:$F$1000,$J28)="","",INDEX(Datos!$F$2:$F$1000,$J28))) | E28: =IF($J28=0,"",IF(INDEX(Datos!$H$2:$H$1000,$J28)="","",INDEX(Datos!$H$2:$H$1000,$J28))) | F28: =IF($J28=0,"",IF(INDEX(Datos!$N$2:$N$1000,$J28)="","",INDEX(Datos!$N$2:$N$1000,$J28))) | G28: =IF($J28=0,"",IF(INDEX(Datos!$M$2:$M$1000,$J28)="","",INDEX(Datos!$M$2:$M$1000,$J28))) | H28: =IF($J28=0,"",INDEX(Datos!$J$2:$J$1000,$J28)&IF(INDEX(Datos!$Q$2:$Q$1000,$J28)="",""," | "&INDEX(Datos!$Q$2:$Q$1000,$J28))) | J28: =IFERROR(MATCH(ROW()-17,Datos!$W$2:$W$1000,0),0) -> 0
A29: =IF($J29=0,"",IF(INDEX(Datos!$A$2:$A$1000,$J29)="","",INDEX(Datos!$A$2:$A$1000,$J29))) | B29: =IF($J29=0,"",IF(INDEX(Datos!$E$2:$E$1000,$J29)="","",INDEX(Datos!$E$2:$E$1000,$J29))) | C29: =IF($J29=0,"",IF(INDEX(Datos!$I$2:$I$1000,$J29)="","",INDEX(Datos!$I$2:$I$1000,$J29))) | D29: =IF($J29=0,"",IF(INDEX(Datos!$F$2:$F$1000,$J29)="","",INDEX(Datos!$F$2:$F$1000,$J29))) | E29: =IF($J29=0,"",IF(INDEX(Datos!$H$2:$H$1000,$J29)="","",INDEX(Datos!$H$2:$H$1000,$J29))) | F29: =IF($J29=0,"",IF(INDEX(Datos!$N$2:$N$1000,$J29)="","",INDEX(Datos!$N$2:$N$1000,$J29))) | G29: =IF($J29=0,"",IF(INDEX(Datos!$M$2:$M$1000,$J29)="","",INDEX(Datos!$M$2:$M$1000,$J29))) | H29: =IF($J29=0,"",INDEX(Datos!$J$2:$J$1000,$J29)&IF(INDEX(Datos!$Q$2:$Q$1000,$J29)="",""," | "&INDEX(Datos!$Q$2:$Q$1000,$J29))) | J29: =IFERROR(MATCH(ROW()-17,Datos!$W$2:$W$1000,0),0) -> 0
... A517: =IF($J517=0,"",IF(INDEX(Datos!$A$2:$A$1000,$J517)="","",INDEX(Datos!$A$2:$A$1000,$J517))) | B517: =IF($J517=0,"",IF(INDEX(Datos!$E$2:$E$1000,$J517)="","",INDEX(Datos!$E$2:$E$1000,$J517))) | C517: =IF($J517=0,"",IF(INDEX(Datos!$I$2:$I$1000,$J517)="","",INDEX(Datos!$I$2:$I$1000,$J517))) | D517: =IF($J517=0,"",IF(INDEX(Datos!$F$2:$F$1000,$J517)="","",INDEX(Datos!$F$2:$F$1000,$J517))) | E517: =IF($J517=0,"",IF(INDEX(Datos!$H$2:$H$1000,$J517)="","",INDEX(Datos!$H$2:$H$1000,$J517))) | F517: =IF($J517=0,"",IF(INDEX(Datos!$N$2:$N$1000,$J517)="","",INDEX(Datos!$N$2:$N$1000,$J517))) | G517: =IF($J517=0,"",IF(INDEX(Datos!$M$2:$M$1000,$J517)="","",INDEX(Datos!$M$2:$M$1000,$J517))) | H517: =IF($J517=0,"",INDEX(Datos!$J$2:$J$1000,$J517)&IF(INDEX(Datos!$Q$2:$Q$1000,$J517)="",""," | "&INDEX(Datos!$Q$2:$Q$1000,$J517))) | J517: =IFERROR(MATCH(ROW()-17,Datos!$W$2:$W$1000,0),0) -> 0

Sheet Datos
A1: Distrito | B1: Servicio | C1: Area de gobierno | D1: Direccion general | E1: Subdireccion / unidad | F1: Contrato | G1: Expediente | H1: Lote | I1: Empresa / UTE | J1: Prestacion | K1: Cobertura | L1: Inicio registrado (ver criterio) | M1: Fin registrado (ver criterio) | N1: Responsable DG | O1: Gestor del contrato | P1: Contacto publicado | Q1: Excepciones / limites | R1: Estado / pendientes | S1: Fuente | T1: ID relacion (PK propuesta) | U1: ID lote (FK propuesta) | X1: ESTADO DE VIGENCIA · 16/10/2026 | Y1: GRUPO/FAMILIA PARA BÚSQUEDA | Z1: CRITERIO VÍNCULO CORPORATIVO | AA1: REVISIÓN | AB1: ESTADO CONTRACTUAL | AC1: COBERTURA DEL LOTE | AD1: FECHAS: CRITERIO | AE1: REVISADO EL | AF1: CLAVES DE GRUPO
A2: Centro | B2: Residuos | C2: Área de Gobierno de Urbanismo, Medio Ambiente y Movilidad | D2: Dirección General de Servicios de Limpieza y Residuos | E2: Subdirección General de Recogida de Residuos | F2: Contenerización, recogida y transporte de residuos | G2: 131/2021/06296 | H2: 1 | I2: FCC MEDIO AMBIENTE, SA | J2: Recogida y transporte habitual | K2: Zona territorial del lote | L2: 44866 | M2: 47057 | N2: Víctor Manuel Sarabia Herrero | O2: No acreditado | P2: 010 / 914 800 010 (atencion municipal, no gestor directo) | Q2: Lote 1: eventos eje Castellana-Prado-Recoletos | R2: Concesión vigente; adjudicataria y fin 31/10/2028 contrastados en registro de concesiones municipal (15/10/2026). | FECHAS REVISADAS: Inicio 01/11/2022 acreditado por formalización de los cuatro lotes. | CONTROL DOCUMENTAL 21/10/2026: Adjudicación y fin publicados. Los cuatro lotes se pueden contrastar en el registro municipal de concesiones. Fin publicado: 31/10/2028. No generalizar ámbito de cada lote. [Base de evidencia: Portal municipal / resolución o resultado oficial consultado] | CONTRASTE ADICIONAL 21/10/2026: FUENTE MUNICIPAL: la concesión registra adjudicación diferenciada en los 4 lotes (FCC, UTE VAO, UTE Sur, CONTENUR) y fin contractual 31/10/2028. | S2: https://contratacion.madrid.es/concesiones/ https://contrataciondelestado.es/FileSystem/servlet/GetDocumentByIdServlet?DocumentIdParam=I52CDqtLbsdgHyWk6Tjc%2BH2t2QGKU1Ro9lcaZmb7V5J4T4CLRYtO18fD2fcADXQg90aL83OqQbUADSXvNu02Vt6kOzxNccJdTRf8umMgorI%3D&cifrado=QUC1GjXXSiLkydRHJBmbpw%3D%3D | T2: REL-0001 | U2: 131/2021/06296|1 | V2: =IF(AND(SUM(IF('Consulta de contratos'!$K$1="",0,1),IF('Consulta de contratos'!$K$2="",0,1),IF('Consulta de contratos'!$K$3="",0,1),IF('Consulta de contratos'!$K$4="",0,1),IF('Consulta de contratos'!$K$5="",0,1),IF('Consulta de contratos'!$K$6="",0,1))>0,OR('Consulta de contratos'!$K$1="",A2='Consulta de contratos'!$K$1),OR('Consulta de contratos'!$K$2="",I2='Consulta de contratos'!$K$2),OR('Consulta de contratos'!$K$3="",C2='Consulta de contratos'!$K$3),OR('Consulta de contratos'!$K$4="",D2='Consulta de contratos'!$K$4),OR('Consulta de contratos'!$K$5="",E2='Consulta de contratos'!$K$5),OR('Consulta de contratos'!$K$6="",IFERROR(ISNUMBER(SEARCH("|"&'Consulta de contratos'!$K$6&"|",AF2)),FALSE))),1,0) -> 0 | W2: =IF(V2=1,SUM($V$2:V2),0) -> 0 | X2: FIN REGISTRADO POSTERIOR · EJECUCIÓN A CONFIRMAR | Y2: FCC | Z2: Grupo/familia pendiente de confirmar legalmente | AA2: 16/10/2026 | AF2: |FCC|
A3: Centro | B3: Residuos | C3: Área de Gobierno de Urbanismo, Medio Ambiente y Movilidad | D3: Dirección General de Servicios de Limpieza y Residuos | E3: Subdirección General de Recogida de Residuos | F3: Contenerización, recogida y transporte de residuos | G3: 131/2021/06296 | H3: 4 | I3: CONTENUR SL | J3: Suministro, mantenimiento y limpieza de contenedores | K3: Toda la ciudad | L3: 44866 | M3: 47057 | N3: Víctor Manuel Sarabia Herrero | O3: No acreditado | P3: 010 / 914 800 010 (atencion municipal, no gestor directo) | Q3: No es vaciado ni recogida habitual | R3: Concesión vigente; adjudicataria y fin 31/10/2028 contrastados en registro de concesiones municipal (15/10/2026). | FECHAS REVISADAS: Inicio 01/11/2022 acreditado por formalización de los cuatro lotes. | CONTROL DOCUMENTAL 21/10/2026: Adjudicación y fin publicados. Los cuatro lotes se pueden contrastar en el registro municipal de concesiones. Fin publicado: 31/10/2028. No generalizar ámbito de cada lote. [Base de evidencia: Portal municipal / resolución o resultado oficial consultado] | CONTRASTE ADICIONAL 21/10/2026: FUENTE MUNICIPAL: la concesión registra adjudicación diferenciada en los 4 lotes (FCC, UTE VAO, UTE Sur, CONTENUR) y fin contractual 31/10/2028. | S3: https://contratacion.madrid.es/concesiones/ https://contrataciondelestado.es/FileSystem/servlet/GetDocumentByIdServlet?DocumentIdParam=I52CDqtLbsdgHyWk6Tjc%2BH2t2QGKU1Ro9lcaZmb7V5J4T4CLRYtO18fD2fcADXQg90aL83OqQbUADSXvNu02Vt6kOzxNccJdTRf8umMgorI%3D&cifrado=QUC1GjXXSiLkydRHJBmbpw%3D%3D | T3: REL-0002 | U3: 131/2021/06296|4 | V3: =IF(AND(SUM(IF('Consulta de contratos'!$K$1="",0,1),IF('Consulta de contratos'!$K$2="",0,1),IF('Consulta de contratos'!$K$3="",0,1),IF('Consulta de contratos'!$K$4="",0,1),IF('Consulta de contratos'!$K$5="",0,1),IF('Consulta de contratos'!$K$6="",0,1))>0,OR('Consulta de contratos'!$K$1="",A3='Consulta de contratos'!$K$1),OR('Consulta de contratos'!$K$2="",I3='Consulta de contratos'!$K$2),OR('Consulta de contratos'!$K$3="",C3='Consulta de contratos'!$K$3),OR('Consulta de contratos'!$K$4="",D3='Consulta de contratos'!$K$4),OR('Consulta de contratos'!$K$5="",E3='Consulta de contratos'!$K$5),OR('Consulta de contratos'!$K$6="",IFERROR(ISNUMBER(SEARCH("|"&'Consulta de contratos'!$K$6&"|",AF3)),FALSE))),1,0) -> 0 | W3: =IF(V3=1,SUM($V$2:V3),0) -> 0 | X3: FIN REGISTRADO POSTERIOR · EJECUCIÓN A CONFIRMAR | Y3: CONTENUR SL | Z3: Agrupación de consulta por nombre de adjudicataria; no consta matriz contrastada. | AA3: 16/10/2026 | AF3: |CONTENUR SL|
A4: Centro | B4: Residuos | C4: Área de Gobierno de Urbanismo, Medio Ambiente y Movilidad | D4: Dirección General de Servicios de Limpieza y Residuos | E4: Subdirección General de Recogida de Residuos | F4: Contenerización, recogida y transporte de residuos | G4: 131/2021/06296 | H4: 3 | I4: UTE 2022 Recogida Madrid Sur | J4: Recogida de pilas y baterias usadas | K4: Toda la ciudad | L4: 44866 | M4: 47057 | N4: Víctor Manuel Sarabia Herrero | O4: No acreditado | P4: 010 / 914 800 010 (atencion municipal, no gestor directo) | Q4: Tarea especial del lote 3 fuera de su zona habitual | R4: Concesión vigente; adjudicataria y fin 31/10/2028 contrastados en registro de concesiones municipal (15/10/2026). | FECHAS REVISADAS: Inicio 01/11/2022 acreditado por formalización de los cuatro lotes. | CONTROL DOCUMENTAL 21/10/2026: Adjudicación y fin publicados. Los cuatro lotes se pueden contrastar en el registro municipal de concesiones. Fin publicado: 31/10/2028. No generalizar ámbito de cada lote. [Base de evidencia: Portal municipal / resolución o resultado oficial consultado] | CONTRASTE ADICIONAL 21/10/2026: FUENTE MUNICIPAL: la concesión registra adjudicación diferenciada en los 4 lotes (FCC, UTE VAO, UTE Sur, CONTENUR) y fin contractual 31/10/2028. | S4: https://contratacion.madrid.es/concesiones/ https://contrataciondelestado.es/FileSystem/servlet/GetDocumentByIdServlet?DocumentIdParam=I52CDqtLbsdgHyWk6Tjc%2BH2t2QGKU1Ro9lcaZmb7V5J4T4CLRYtO18fD2fcADXQg90aL83OqQbUADSXvNu02Vt6kOzxNccJdTRf8umMgorI%3D&cifrado=QUC1GjXXSiLkydRHJBmbpw%3D%3D | T4: REL-0003 | U4: 131/2021/06296|3 | V4: =IF(AND(SUM(IF('Consulta de contratos'!$K$1="",0,1),IF('Consulta de contratos'!$K$2="",0,1),IF('Consulta de contratos'!$K$3="",0,1),IF('Consulta de contratos'!$K$4="",0,1),IF('Consulta de contratos'!$K$5="",0,1),IF('Consulta de contratos'!$K$6="",0,1))>0,OR('Consulta de contratos'!$K$1="",A4='Consulta de contratos'!$K$1),OR('Consulta de contratos'!$K$2="",I4='Consulta de contratos'!$K$2),OR('Consulta de contratos'!$K$3="",C4='Consulta de contratos'!$K$3),OR('Consulta de contratos'!$K$4="",D4='Consulta de contratos'!$K$4),OR('Consulta de contratos'!$K$5="",E4='Consulta de contratos'!$K$5),OR('Consulta de contratos'!$K$6="",IFERROR(ISNUMBER(SEARCH("|"&'Consulta de contratos'!$K$6&"|",AF4)),FALSE))),1,0) -> 0 | W4: =IF(V4=1,SUM($V$2:V4),0) -> 0 | X4: FIN REGISTRADO POSTERIOR · EJECUCIÓN A CONFIRMAR | Y4: PREZERO | URBASER | Z4: UTE: vínculo comercial; no implica propiedad | AA4: 16/10/2026 | AF4: |PREZERO|URBASER|
A5: Centro | B5: Residuos | C5: Área de Gobierno de Urbanismo, Medio Ambiente y Movilidad | D5: Dirección General de Servicios de Limpieza y Residuos | E5: Subdirección General de Recogida de Residuos | F5: Asistencia técnica para el mantenimiento, ampliación y mejora continua del sistema de gestión de la información de limpieza urbana, recogida de residuos y equipamientos urbanos | G5: 300/2025/00411 | H5: Sin lotes | I5: APORTA PLATAFORMA COOPERATIVA SCCL | J5: Mantenimiento y mejora del sistema de informacion | K5: Ambito municipal; no contrato propio del distrito | M5: 46850 | N5: Víctor Manuel Sarabia Herrero | O5: No acreditado | P5: 010 / 914 800 010 (atencion municipal, no gestor directo) | R5: Adjudicado 27/01/2026 y formalizado 08/04/2026. Fin publicado 07/04/2028 (posible prórroga 12 meses). Inicio de prestación no acreditado. | FECHAS SIN ACREDITAR: Formalización 08/04/2026 y fin en agregador 07/04/2028; no consta fecha independiente de inicio de prestación. La formalización no se convierte en inicio automático. | FUENTES REVISADAS 21/10/2026: Ayuntamiento publica objeto y pliegos; registro TED del contrato identifica formalización el 08/04/2026 y adjudicataria Aporta. No equivale a fecha de inicio operativo. | CONTROL DOCUMENTAL 21/10/2026: Adjudicataria identificada. APORTA PLATAFORMA COOPERATIVA figura en la base y en fichas de licitación; comprobar firma e hitos en el expediente. [Base de evidencia: Datos confrontados con referencias aportadas; no hay resolución individual corroborada] | CONTRASTE ADICIONAL 21/10/2026: ADJUDICACIÓN: APORTA PLATAFORMA COOPERATIVA SCCL, resolución de 27/01/2026, contrastada con publicación de licitación. | S5: https://contratos.gobierto.es/adjudicatarios/aporta-plataforma-cooperativa-sccl?locale=es https://www.madrid.es/portales/munimadrid/es/Inicio/Medio-ambiente/Limpieza-urbana/Contrato-de-servicio-de-asistencia-tecnica/?vgnextchannel=ddd2a694fde40910VgnVCM2000001f4a900aRCRD&vgnextfmt=default&vgnextoid=7c07475398a4e910VgnVCM200000f921e388RCRD https://contratos.gobierto.es/licitaciones/4668721?locale=es | T5: REL-0004 | U5: 300/2025/00411|Sin lotes | V5: =IF(AND(SUM(IF('Consulta de contratos'!$K$1="",0,1),IF('Consulta de contratos'!$K$2="",0,1),IF('Consulta de contratos'!$K$3="",0,1),IF('Consulta de contratos'!$K$4="",0,1),IF('Consulta de contratos'!$K$5="",0,1),IF('Consulta de contratos'!$K$6="",0,1))>0,OR('Consulta de contratos'!$K$1="",A5='Consulta de contratos'!$K$1),OR('Consulta de contratos'!$K$2="",I5='Consulta de contratos'!$K$2),OR('Consulta de contratos'!$K$3="",C5='Consulta de contratos'!$K$3),OR('Consulta de contratos'!$K$4="",D5='Consulta de contratos'!$K$4),OR('Consulta de contratos'!$K$5="",E5='Consulta de contratos'!$K$5),OR('Consulta de contratos'!$K$6="",IFERROR(ISNUMBER(SEARCH("|"&'Consulta de contratos'!$K$6&"|",AF5)),FALSE))),1,0) -> 0 | W5: =IF(V5=1,SUM($V$2:V5),0) -> 0 | X5: FIN REGISTRADO POSTERIOR · EJECUCIÓN A CONFIRMAR | Y5: APORTA PLATAFORMA COOPERATIVA SCCL | Z5: Agrupación de consulta por nombre de adjudicataria; no consta matriz contrastada. | AA5: 16/10/2026 | AF5: |APORTA PLATAFORMA COOPERATIVA SCCL|
A6: Centro | B6: Residuos | C6: Área de Gobierno de Urbanismo, Medio Ambiente y Movilidad | D6: Dirección General de Servicios de Limpieza y Residuos | E6: Subdirección General de Recogida de Residuos | F6: Gestión del servicio de explotación de puntos limpios, centros de reutilización de residuos y saneamiento de viviendas | G6: 300/2023/00593 | H6: Sin lotes | I6: PREZERO ESPAÑA SAU | J6: Gestión de puntos limpios y centros de reutilización; saneamientos por requerimiento. | K6: Ambito municipal; ubicaciones concretas no incluidas | L6: 45622 | M6: 47447 | N6: Víctor Manuel Sarabia Herrero | O6: No acreditado | P6: 010 / 914 800 010 (atencion municipal, no gestor directo) | Q6: Saneamiento no es limpieza domestica ordinaria | R6: Vigente según Ayuntamiento; adjudicataria PREZERO acreditada (24/10/2024). Inicio contractual y fecha fin exacta sin acreditar. | FECHAS REVISADAS: Vigencia: 26/11/2024–25/11/2029. Inicio oficial; fin ordinario calculado por cinco años contractuales sin prórroga. | CONTROL DOCUMENTAL 21/10/2026: Adjudicataria identificada. PREZERO ESPAÑA figura adjudicataria de puntos limpios. El contrato es municipal; no son 21 concesiones independientes. [Base de evidencia: Datos confrontados con referencias aportadas; no hay resolución individual corroborada] | CONTRASTE ADICIONAL 21/10/2026: ADJUDICACIÓN: PREZERO ESPAÑA SA, 24/10/2024. El Ayuntamiento dispone de ficha oficial del contrato; compruébese formalización para fechas exactas. | S6: https://contratos.gobierto.es/licitaciones/4336157 https://contrataciondelestado.es/FileSystem/servlet/GetDocumentByIdServlet?DocumentIdParam=DX1ZAvwzaIUStPoibgXBVeTGIJOgffe86rdC19dt4dT5lTaSGg5Vq9cT4fT6Jv75jYAipcFv6g1zHenSv4lINo4IQyA7QON0MW%2BNRBCDa6cZyAJWGsSt0OzTSTyw9JAs&cifrado=QUC1GjXXSiLkydRHJBmbpw%3D%3D https://www.madrid.es/UnidadesDescentralizadas/LimpiezaUrbanaYResiduos/CONTRATOS_DG/CONTRATO-RES_PuntosLimpios/DocumentoPliegos_ContratoPuntosLimpios.pdf https://www.madrid.es/portales/munimadrid/es/Inicio/Medio-ambiente/Recogida-de-residuos/Contrato-de-servicios-de-explotacion-de-puntos-limpios-centros-de-reutilizacion-de-residuos-y-saneamiento-de-viviendas-en-la-ciudad-de-Madrid/?vgnextchannel=f81379ed268fe410VgnVCM1000000b205a0aRCRD&vgnextfmt=default&vgnextoid=8177150aabc46710VgnVCM2000001f4a900aRCRD | T6: REL-0005 | U6: 300/2023/00593|Sin lotes | V6: =IF(AND(SUM(IF('Consulta de contratos'!$K$1="",0,1),IF('Consulta de contratos'!$K$2="",0,1),IF('Consulta de contratos'!$K$3="",0,1),IF('Consulta de contratos'!$K$4="",0,1),IF('Consulta de contratos'!$K$5="",0,1),IF('Consulta de contratos'!$K$6="",0,1))>0,OR('Consulta de contratos'!$K$1="",A6='Consulta de contratos'!$K$1),OR('Consulta de contratos'!$K$2="",I6='Consulta de contratos'!$K$2),OR('Consulta de contratos'!$K$3="",C6='Consulta de contratos'!$K$3),OR('Consulta de contratos'!$K$4="",D6='Consulta de contratos'!$K$4),OR('Consulta de contratos'!$K$5="",E6='Consulta de contratos'!$K$5),OR('Consulta de contratos'!$K$6="",IFERROR(ISNUMBER(SEARCH("|"&'Consulta de contratos'!$K$6&"|",AF6)),FALSE))),1,0) -> 0 | W6: =IF(V6=1,SUM($V$2:V6),0) -> 0 | X6: FIN REGISTRADO POSTERIOR · EJECUCIÓN A CONFIRMAR | Y6: PREZERO | Z6: Grupo/familia pendiente de confirmar legalmente | AA6: 16/10/2026 | AF6: |PREZERO|
A7: Centro | B7: Residuos | C7: Área de Gobierno de Urbanismo, Medio Ambiente y Movilidad | D7: Dirección General de Servicios de Limpieza y Residuos | E7: Subdirección General de Recogida de Residuos | F7: Programa de actividades de sensibilización sobre separación de residuos y limpieza del espacio público | G7: 300/2026/00024 | H7: Sin lotes | I7: TALHER, S.A. | J7: Actividades educativas y de sensibilizacion | K7: Ambito municipal; no acredita actividad en cada distrito | N7: Víctor Manuel Sarabia Herrero | O7: No acreditado | P7: 010 / 914 800 010 (atencion municipal, no gestor directo) | Q7: Adjudicación publicada en datos de PLACSP; formalización e inicio efectivos sin contrastar. | ATENCIÓN · CONTRASTE 23/10/2026: el portal municipal incluye este expediente entre los contratos en vigor, mientras un agregador lo presenta como «Desistida». La resolución de adjudicación, la formalización y el inicio efectivo requieren comprobación directa. | R7: ADJUDICACIÓN 30/09/2026 A TALHER, S.A. (1.432.107 € sin IVA) recogida en LicitaLens a partir de PLACSP. Pendiente de verificar resolución y fecha de formalización en documento oficial; no certificar inicio efectivo. | CONTROL DOCUMENTAL 21/10/2026: Adjudicación localizada. Adjudicación a TALHER encontrada en plataformas que reproducen PLACSP; la resolución y la fecha de ejecución requieren lectura directa. [Base de evidencia: Ficha individual de publicación / agregador contrastada] | CONTRASTE DE FUENTES 23/10/2026: ficha municipal lo relaciona entre contratos en vigor; Gobierto muestra estado «Desistida», pese a reflejar datos de adjudicación del 30/09/2026. No tratar la formalización, la entrada en servicio ni la vigencia como acreditadas sin resolución. | S7: https://www.madrid.es/portales/munimadrid/es/Inicio/El-Ayuntamiento/Publicaciones/Listado-de-Publicaciones/Contratos-de-Recogida-de-Residuos/?vgnextchannel=f1aebadb6b997010VgnVCM100000dc0ca8c0RCRD&vgnextfmt=default&vgnextoid=429f71adf3d56910VgnVCM2000001f4a900aRCRD https://contratos.gobierto.es/licitaciones/5108890 https://licitalens.com/empresa/A08602815 https://www.madrid.es/portales/munimadrid/es/Inicio/Medio-ambiente/Recogida-de-residuos/Actividades-y-eventos/Contrato-de-servicio-de-actividades-de-sensibilizacion/?vgnextchannel=d04bbb21278fe410VgnVCM1000000b205a0aRCRD&vgnextfmt=default&vgnextoid=1d1f49ec5caef910VgnVCM200000f921e388RCRD | T7: REL-0006 | U7: 300/2026/00024|Sin lotes | V7: =IF(AND(SUM(IF('Consulta de contratos'!$K$1="",0,1),IF('Consulta de contratos'!$K$2="",0,1),IF('Consulta de contratos'!$K$3="",0,1),IF('Consulta de contratos'!$K$4="",0,1),IF('Consulta de contratos'!$K$5="",0,1),IF('Consulta de contratos'!$K$6="",0,1))>0,OR('Consulta de contratos'!$K$1="",A7='Consulta de contratos'!$K$1),OR('Consulta de contratos'!$K$2="",I7='Consulta de contratos'!$K$2),OR('Consulta de contratos'!$K$3="",C7='Consulta de contratos'!$K$3),OR('Consulta de contratos'!$K$4="",D7='Consulta de contratos'!$K$4),OR('Consulta de contratos'!$K$5="",E7='Consulta de contratos'!$K$5),OR('Consulta de contratos'!$K$6="",IFERROR(ISNUMBER(SEARCH("|"&'Consulta de contratos'!$K$6&"|",AF7)),FALSE))),1,0) -> 0 | W7: =IF(V7=1,SUM($V$2:V7),0) -> 0 | X7: ADJUDICACIÓN PUBLICADA EN DATOS PLACSP · FORMALIZACIÓN POR CONTRASTAR | Y7: CLECE | Z7: Grupo de empresa contrastado en fuente corporativa: https://clece.es/es/listado-clece-filiales/ | AA7: 16/10/2026 | AF7: |CLECE|
A8: Arganzuela | B8: Residuos | C8: Área de Gobierno de Urbanismo, Medio Ambiente y Movilidad | D8: Dirección General de Servicios de Limpieza y Residuos | E8: Subdirección General de Recogida de Residuos | F8: Contenerización, recogida y transporte de residuos | G8: 131/2021/06296 | H8: 3 | I8: UTE 2022 Recogida Madrid Sur | J8: Recogida y transporte habitual | K8: Zona territorial del lote | L8: 44866 | M8: 47057 | N8: Víctor Manuel Sarabia Herrero | O8: No acreditado | P8: 010 / 914 800 010 (atencion municipal, no gestor directo) | R8: Concesión vigente; adjudicataria y fin 31/10/2028 contrastados en registro de concesiones municipal (15/10/2026). | FECHAS REVISADAS: Inicio 01/11/2022 acreditado por formalización de los cuatro lotes. | CONTROL DOCUMENTAL 21/10/2026: Adjudicación y fin publicados. Los cuatro lotes se pueden contrastar en el registro municipal de concesiones. Fin publicado: 31/10/2028. No generalizar ámbito de cada lote. [Base de evidencia: Portal municipal / resolución o resultado oficial consultado] | CONTRASTE ADICIONAL 21/10/2026: FUENTE MUNICIPAL: la concesión registra adjudicación diferenciada en los 4 lotes (FCC, UTE VAO, UTE Sur, CONTENUR) y fin contractual 31/10/2028. | S8: https://contratacion.madrid.es/concesiones/ https://contrataciondelestado.es/FileSystem/servlet/GetDocumentByIdServlet?DocumentIdParam=I52CDqtLbsdgHyWk6Tjc%2BH2t2QGKU1Ro9lcaZmb7V5J4T4CLRYtO18fD2fcADXQg90aL83OqQbUADSXvNu02Vt6kOzxNccJdTRf8umMgorI%3D&cifrado=QUC1GjXXSiLkydRHJBmbpw%3D%3D | T8: REL-0007 | U8: 131/2021/06296|3 | V8: =IF(AND(SUM(IF('Consulta de contratos'!$K$1="",0,1),IF('Consulta de contratos'!$K$2="",0,1),IF('Consulta de contratos'!$K$3="",0,1),IF('Consulta de contratos'!$K$4="",0,1),IF('Consulta de contratos'!$K$5="",0,1),IF('Consulta de contratos'!$K$6="",0,1))>0,OR('Consulta de contratos'!$K$1="",A8='Consulta de contratos'!$K$1),OR('Consulta de contratos'!$K$2="",I8='Consulta de contratos'!$K$2),OR('Consulta de contratos'!$K$3="",C8='Consulta de contratos'!$K$3),OR('Consulta de contratos'!$K$4="",D8='Consulta de contratos'!$K$4),OR('Consulta de contratos'!$K$5="",E8='Consulta de contratos'!$K$5),OR('Consulta de contratos'!$K$6="",IFERROR(ISNUMBER(SEARCH("|"&'Consulta de contratos'!$K$6&"|",AF8)),FALSE))),1,0) -> 0 | W8: =IF(V8=1,SUM($V$2:V8),0) -> 0 | X8: FIN REGISTRADO POSTERIOR · EJECUCIÓN A CONFIRMAR | Y8: PREZERO | URBASER | Z8: UTE: vínculo comercial; no implica propiedad | AA8: 16/10/2026 | AF8: |PREZERO|URBASER|
A9: Arganzuela | B9: Residuos | C9: Área de Gobierno de Urbanismo, Medio Ambiente y Movilidad | D9: Dirección General de Servicios de Limpieza y Residuos | E9: Subdirección General de Recogida de Residuos | F9: Contenerización, recogida y transporte de residuos | G9: 131/2021/06296 | H9: 4 | I9: CONTENUR SL | J9: Suministro, mantenimiento y limpieza de contenedores | K9: Toda la ciudad | L9: 44866 | M9: 47057 | N9: Víctor Manuel Sarabia Herrero | O9: No acreditado | P9: 010 / 914 800 010 (atencion municipal, no gestor directo) | Q9: No es vaciado ni recogida habitual | R9: Concesión vigente; adjudicataria y fin 31/10/2028 contrastados en registro de concesiones municipal (15/10/2026). | FECHAS REVISADAS: Inicio 01/11/2022 acreditado por formalización de los cuatro lotes. | CONTROL DOCUMENTAL 21/10/2026: Adjudicación y fin publicados. Los cuatro lotes se pueden contrastar en el registro municipal de concesiones. Fin publicado: 31/10/2028. No generalizar ámbito de cada lote. [Base de evidencia: Portal municipal / resolución o resultado oficial consultado] | CONTRASTE ADICIONAL 21/10/2026: FUENTE MUNICIPAL: la concesión registra adjudicación diferenciada en los 4 lotes (FCC, UTE VAO, UTE Sur, CONTENUR) y fin contractual 31/10/2028. | S9: https://contratacion.madrid.es/concesiones/ https://contrataciondelestado.es/FileSystem/servlet/GetDocumentByIdServlet?DocumentIdParam=I52CDqtLbsdgHyWk6Tjc%2BH2t2QGKU1Ro9lcaZmb7V5J4T4CLRYtO18fD2fcADXQg90aL83OqQbUADSXvNu02Vt6kOzxNccJdTRf8umMgorI%3D&cifrado=QUC1GjXXSiLkydRHJBmbpw%3D%3D | T9: REL-0008 | U9: 131/2021/06296|4 | V9: =IF(AND(SUM(IF('Consulta de contratos'!$K$1="",0,1),IF('Consulta de contratos'!$K$2="",0,1),IF('Consulta de contratos'!$K$3="",0,1),IF('Consulta de contratos'!$K$4="",0,1),IF('Consulta de contratos'!$K$5="",0,1),IF('Consulta de contratos'!$K$6="",0,1))>0,OR('Consulta de contratos'!$K$1="",A9='Consulta de contratos'!$K$1),OR('Consulta de contratos'!$K$2="",I9='Consulta de contratos'!$K$2),OR('Consulta de contratos'!$K$3="",C9='Consulta de contratos'!$K$3),OR('Consulta de contratos'!$K$4="",D9='Consulta de contratos'!$K$4),OR('Consulta de contratos'!$K$5="",E9='Consulta de contratos'!$K$5),OR('Consulta de contratos'!$K$6="",IFERROR(ISNUMBER(SEARCH("|"&'Consulta de contratos'!$K$6&"|",AF9)),FALSE))),1,0) -> 0 | W9: =IF(V9=1,SUM($V$2:V9),0) -> 0 | X9: FIN REGISTRADO POSTERIOR · EJECUCIÓN A CONFIRMAR | Y9: CONTENUR SL | Z9: Agrupación de consulta por nombre de adjudicataria; no consta matriz contrastada. | AA9: 16/10/2026 | AF9: |CONTENUR SL|
A10: Arganzuela | B10: Residuos | C10: Área de Gobierno de Urbanismo, Medio Ambiente y Movilidad | D10: Dirección General de Servicios de Limpieza y Residuos | E10: Subdirección General de Recogida de Residuos | F10: Contenerización, recogida y transporte de residuos | G10: 131/2021/06296 | H10: 3 | I10: UTE 2022 Recogida Madrid Sur | J10: Recogida de pilas y baterias usadas | K10: Toda la ciudad | L10: 44866 | M10: 47057 | N10: Víctor Manuel Sarabia Herrero | O10: No acreditado | P10: 010 / 914 800 010 (atencion municipal, no gestor directo) | Q10: Tarea especial del lote 3 fuera de su zona habitual | R10: Concesión vigente; adjudicataria y fin 31/10/2028 contrastados en registro de concesiones municipal (15/10/2026). | FECHAS REVISADAS: Inicio 01/11/2022 acreditado por formalización de los cuatro lotes. | CONTROL DOCUMENTAL 21/10/2026: Adjudicación y fin publicados. Los cuatro lotes se pueden contrastar en el registro municipal de concesiones. Fin publicado: 31/10/2028. No generalizar ámbito de cada lote. [Base de evidencia: Portal municipal / resolución o resultado oficial consultado] | CONTRASTE ADICIONAL 21/10/2026: FUENTE MUNICIPAL: la concesión registra adjudicación diferenciada en los 4 lotes (FCC, UTE VAO, UTE Sur, CONTENUR) y fin contractual 31/10/2028. | S10: https://contratacion.madrid.es/concesiones/ https://contrataciondelestado.es/FileSystem/servlet/GetDocumentByIdServlet?DocumentIdParam=I52CDqtLbsdgHyWk6Tjc%2BH2t2QGKU1Ro9lcaZmb7V5J4T4CLRYtO18fD2fcADXQg90aL83OqQbUADSXvNu02Vt6kOzxNccJdTRf8umMgorI%3D&cifrado=QUC1GjXXSiLkydRHJBmbpw%3D%3D | T10: REL-0009 | U10: 131/2021/06296|3 | V10: =IF(AND(SUM(IF('Consulta de contratos'!$K$1="",0,1),IF('Consulta de contratos'!$K$2="",0,1),IF('Consulta de contratos'!$K$3="",0,1),IF('Consulta de contratos'!$K$4="",0,1),IF('Consulta de contratos'!$K$5="",0,1),IF('Consulta de contratos'!$K$6="",0,1))>0,OR('Consulta de contratos'!$K$1="",A10='Consulta de contratos'!$K$1),OR('Consulta de contratos'!$K$2="",I10='Consulta de contratos'!$K$2),OR('Consulta de contratos'!$K$3="",C10='Consulta de contratos'!$K$3),OR('Consulta de contratos'!$K$4="",D10='Consulta de contratos'!$K$4),OR('Consulta de contratos'!$K$5="",E10='Consulta de contratos'!$K$5),OR('Consulta de contratos'!$K$6="",IFERROR(ISNUMBER(SEARCH("|"&'Consulta de contratos'!$K$6&"|",AF10)),FALSE))),1,0) -> 0 | W10: =IF(V10=1,SUM($V$2:V10),0) -> 0 | X10: FIN REGISTRADO POSTERIOR · EJECUCIÓN A CONFIRMAR | Y10: PREZERO | URBASER | Z10: UTE: vínculo comercial; no implica propiedad | AA10: 16/10/2026 | AF10: |PREZERO|URBASER|
A11: Arganzuela | B11: Residuos | C11: Área de Gobierno de Urbanismo, Medio Ambiente y Movilidad | D11: Dirección General de Servicios de Limpieza y Residuos | E11: Subdirección General de Recogida de Residuos | F11: Asistencia técnica para el mantenimiento, ampliación y mejora continua del sistema de gestión de la información de limpieza urbana, recogida de residuos y equipamientos urbanos | G11: 300/2025/00411 | H11: Sin lotes | I11: APORTA PLATAFORMA COOPERATIVA SCCL | J11: Mantenimiento y mejora del sistema de informacion | K11: Ambito municipal; no contrato propio del distrito | M11: 46850 | N11: Víctor Manuel Sarabia Herrero | O11: No acreditado | P11: 010 / 914 800 010 (atencion municipal, no gestor directo) | R11: Adjudicado 27/01/2026 y formalizado 08/04/2026. Fin publicado 07/04/2028 (posible prórroga 12 meses). Inicio de prestación no acreditado. | FECHAS SIN ACREDITAR: Formalización 08/04/2026 y fin en agregador 07/04/2028; no consta fecha independiente de inicio de prestación. La formalización no se convierte en inicio automático. | FUENTES REVISADAS 21/10/2026: Ayuntamiento publica objeto y pliegos; registro TED del contrato identifica formalización el 08/04/2026 y adjudicataria Aporta. No equivale a fecha de inicio operativo. | CONTROL DOCUMENTAL 21/10/2026: Adjudicataria identificada. APORTA PLATAFORMA COOPERATIVA figura en la base y en fichas de licitación; comprobar firma e hitos en el expediente. [Base de evidencia: Datos confrontados con referencias aportadas; no hay resolución individual corroborada] | CONTRASTE ADICIONAL 21/10/2026: ADJUDICACIÓN: APORTA PLATAFORMA COOPERATIVA SCCL, resolución de 27/01/2026, contrastada con publicación de licitación. | S11: https://contratos.gobierto.es/adjudicatarios/aporta-plataforma-cooperativa-sccl?locale=es https://www.madrid.es/portales/munimadrid/es/Inicio/Medio-ambiente/Limpieza-urbana/Contrato-de-servicio-de-asistencia-tecnica/?vgnextchannel=ddd2a694fde40910VgnVCM2000001f4a900aRCRD&vgnextfmt=default&vgnextoid=7c07475398a4e910VgnVCM200000f921e388RCRD https://contratos.gobierto.es/licitaciones/4668721?locale=es | T11: REL-0010 | U11: 300/2025/00411|Sin lotes | V11: =IF(AND(SUM(IF('Consulta de contratos'!$K$1="",0,1),IF('Consulta de contratos'!$K$2="",0,1),IF('Consulta de contratos'!$K$3="",0,1),IF('Consulta de contratos'!$K$4="",0,1),IF('Consulta de contratos'!$K$5="",0,1),IF('Consulta de contratos'!$K$6="",0,1))>0,OR('Consulta de contratos'!$K$1="",A11='Consulta de contratos'!$K$1),OR('Consulta de contratos'!$K$2="",I11='Consulta de contratos'!$K$2),OR('Consulta de contratos'!$K$3="",C11='Consulta de contratos'!$K$3),OR('Consulta de contratos'!$K$4="",D11='Consulta de contratos'!$K$4),OR('Consulta de contratos'!$K$5="",E11='Consulta de contratos'!$K$5),OR('Consulta de contratos'!$K$6="",IFERROR(ISNUMBER(SEARCH("|"&'Consulta de contratos'!$K$6&"|",AF11)),FALSE))),1,0) -> 0 | W11: =IF(V11=1,SUM($V$2:V11),0) -> 0 | X11: FIN REGISTRADO POSTERIOR · EJECUCIÓN A CONFIRMAR | Y11: APORTA PLATAFORMA COOPERATIVA SCCL | Z11: Agrupación de consulta por nombre de adjudicataria; no consta matriz contrastada. | AA11: 16/10/2026 | AF11: |APORTA PLATAFORMA COOPERATIVA SCCL|
A12: Arganzuela | B12: Residuos | C12: Área de Gobierno de Urbanismo, Medio Ambiente y Movilidad | D12: Dirección General de Servicios de Limpieza y Residuos | E12: Subdirección General de Recogida de Residuos | F12: Gestión del servicio de explotación de puntos limpios, centros de reutilización de residuos y saneamiento de viviendas | G12: 300/2023/00593 | H12: Sin lotes | I12: PREZERO ESPAÑA SAU | J12: Gestión de puntos limpios y centros de reutilización; saneamientos por requerimiento. | K12: Ambito municipal; ubicaciones concretas no incluidas | L12: 45622 | M12: 47447 | N12: Víctor Manuel Sarabia Herrero | O12: No acreditado | P12: 010 / 914 800 010 (atencion municipal, no gestor directo) | Q12: Saneamiento no es limpieza domestica ordinaria | R12: Vigente según Ayuntamiento; adjudicataria PREZERO acreditada (24/10/2024). Inicio contractual y fecha fin exacta sin acreditar. | FECHAS REVISADAS: Vigencia: 26/11/2024–25/11/2029. Inicio oficial; fin ordinario calculado por cinco años contractuales sin prórroga. | CONTROL DOCUMENTAL 21/10/2026: Adjudicataria identificada. PREZERO ESPAÑA figura adjudicataria de puntos limpios. El contrato es municipal; no son 21 concesiones independientes. [Base de evidencia: Datos confrontados con referencias aportadas; no hay resolución individual corroborada] | CONTRASTE ADICIONAL 21/10/2026: ADJUDICACIÓN: PREZERO ESPAÑA SA, 24/10/2024. El Ayuntamiento dispone de ficha oficial del contrato; compruébese formalización para fechas exactas. | S12: https://contratos.gobierto.es/licitaciones/4336157 https://contrataciondelestado.es/FileSystem/servlet/GetDocumentByIdServlet?DocumentIdParam=DX1ZAvwzaIUStPoibgXBVeTGIJOgffe86rdC19dt4dT5lTaSGg5Vq9cT4fT6Jv75jYAipcFv6g1zHenSv4lINo4IQyA7QON0MW%2BNRBCDa6cZyAJWGsSt0OzTSTyw9JAs&cifrado=QUC1GjXXSiLkydRHJBmbpw%3D%3D https://www.madrid.es/UnidadesDescentralizadas/LimpiezaUrbanaYResiduos/CONTRATOS_DG/CONTRATO-RES_PuntosLimpios/DocumentoPliegos_ContratoPuntosLimpios.pdf https://www.madrid.es/portales/munimadrid/es/Inicio/Medio-ambiente/Recogida-de-residuos/Contrato-de-servicios-de-explotacion-de-puntos-limpios-centros-de-reutilizacion-de-residuos-y-saneamiento-de-viviendas-en-la-ciudad-de-Madrid/?vgnextchannel=f81379ed268fe410VgnVCM1000000b205a0aRCRD&vgnextfmt=default&vgnextoid=8177150aabc46710VgnVCM2000001f4a900aRCRD | T12: REL-0011 | U12: 300/2023/00593|Sin lotes | V12: =IF(AND(SUM(IF('Consulta de contratos'!$K$1="",0,1),IF('Consulta de contratos'!$K$2="",0,1),IF('Consulta de contratos'!$K$3="",0,1),IF('Consulta de contratos'!$K$4="",0,1),IF('Consulta de contratos'!$K$5="",0,1),IF('Consulta de contratos'!$K$6="",0,1))>0,OR('Consulta de contratos'!$K$1="",A12='Consulta de contratos'!$K$1),OR('Consulta de contratos'!$K$2="",I12='Consulta de contratos'!$K$2),OR('Consulta de contratos'!$K$3="",C12='Consulta de contratos'!$K$3),OR('Consulta de contratos'!$K$4="",D12='Consulta de contratos'!$K$4),OR('Consulta de contratos'!$K$5="",E12='Consulta de contratos'!$K$5),OR('Consulta de contratos'!$K$6="",IFERROR(ISNUMBER(SEARCH("|"&'Consulta de contratos'!$K$6&"|",AF12)),FALSE))),1,0) -> 0 | W12: =IF(V12=1,SUM($V$2:V12),0) -> 0 | X12: FIN REGISTRADO POSTERIOR · EJECUCIÓN A CONFIRMAR | Y12: PREZERO | Z12: Grupo/familia pendiente de confirmar legalmente | AA12: 16/10/2026 | AF12: |PREZERO|
A13: Arganzuela | B13: Residuos | C13: Área de Gobierno de Urbanismo, Medio Ambiente y Movilidad | D13: Dirección General de Servicios de Limpieza y Residuos | E13: Subdirección General de Recogida de Residuos | F13: Programa de actividades de sensibilización sobre separación de residuos y limpieza del espacio público | G13: 300/2026/00024 | H13: Sin lotes | I13: TALHER, S.A. | J13: Actividades educativas y de sensibilizacion | K13: Ambito municipal; no acredita actividad en cada distrito | N13: Víctor Manuel Sarabia Herrero | O13: No acreditado | P13: 010 / 914 800 010 (atencion municipal, no gestor directo) | Q13: Adjudicación publicada en datos de PLACSP; formalización e inicio efectivos sin contrastar. | ATENCIÓN · CONTRASTE 23/10/2026: el portal municipal incluye este expediente entre los contratos en vigor, mientras un agregador lo presenta como «Desistida». La resolución de adjudicación, la formalización y el inicio efectivo requieren comprobación directa. | R13: ADJUDICACIÓN 30/09/2026 A TALHER, S.A. (1.432.107 € sin IVA) recogida en LicitaLens a partir de PLACSP. Pendiente de verificar resolución y fecha de formalización en documento oficial; no certificar inicio efectivo. | CONTROL DOCUMENTAL 21/10/2026: Adjudicación localizada. Adjudicación a TALHER encontrada en plataformas que reproducen PLACSP; la resolución y la fecha de ejecución requieren lectura directa. [Base de evidencia: Ficha individual de publicación / agregador contrastada] | CONTRASTE DE FUENTES 23/10/2026: ficha municipal lo relaciona entre contratos en vigor; Gobierto muestra estado «Desistida», pese a reflejar datos de adjudicación del 30/09/2026. No tratar la formalización, la entrada en servicio ni la vigencia como acreditadas sin resolución. | S13: https://www.madrid.es/portales/munimadrid/es/Inicio/El-Ayuntamiento/Publicaciones/Listado-de-Publicaciones/Contratos-de-Recogida-de-Residuos/?vgnextchannel=f1aebadb6b997010VgnVCM100000dc0ca8c0RCRD&vgnextfmt=default&vgnextoid=429f71adf3d56910VgnVCM2000001f4a900aRCRD https://contratos.gobierto.es/licitaciones/5108890 https://licitalens.com/empresa/A08602815 https://www.madrid.es/portales/munimadrid/es/Inicio/Medio-ambiente/Recogida-de-residuos/Actividades-y-eventos/Contrato-de-servicio-de-actividades-de-sensibilizacion/?vgnextchannel=d04bbb21278fe410VgnVCM1000000b205a0aRCRD&vgnextfmt=default&vgnextoid=1d1f49ec5caef910VgnVCM200000f921e388RCRD | T13: REL-0012 | U13: 300/2026/00024|Sin lotes | V13: =IF(AND(SUM(IF('Consulta de contratos'!$K$1="",0,1),IF('Consulta de contratos'!$K$2="",0,1),IF('Consulta de contratos'!$K$3="",0,1),IF('Consulta de contratos'!$K$4="",0,1),IF('Consulta de contratos'!$K$5="",0,1),IF('Consulta de contratos'!$K$6="",0,1))>0,OR('Consulta de contratos'!$K$1="",A13='Consulta de contratos'!$K$1),OR('Consulta de contratos'!$K$2="",I13='Consulta de contratos'!$K$2),OR('Consulta de contratos'!$K$3="",C13='Consulta de contratos'!$K$3),OR('Consulta de contratos'!$K$4="",D13='Consulta de contratos'!$K$4),OR('Consulta de contratos'!$K$5="",E13='Consulta de contratos'!$K$5),OR('Consulta de contratos'!$K$6="",IFERROR(ISNUMBER(SEARCH("|"&'Consulta de contratos'!$K$6&"|",AF13)),FALSE))),1,0) -> 0 | W13: =IF(V13=1,SUM($V$2:V13),0) -> 0 | X13: ADJUDICACIÓN PUBLICADA EN DATOS PLACSP · FORMALIZACIÓN POR CONTRASTAR | Y13: CLECE | Z13: Grupo de empresa contrastado en fuente corporativa: https://clece.es/es/listado-clece-filiales/ | AA13: 16/10/2026 | AF13: |CLECE|
A14: Retiro | B14: Residuos | C14: Área de Gobierno de Urbanismo, Medio Ambiente y Movilidad | D14: Dirección General de Servicios de Limpieza y Residuos | E14: Subdirección General de Recogida de Residuos | F14: Contenerización, recogida y transporte de residuos | G14: 131/2021/06296 | H14: 2 | I14: UTE Recogida Madrid VAO | J14: Recogida y transporte habitual | K14: Zona territorial del lote | L14: 44866 | M14: 47057 | N14: Víctor Manuel Sarabia Herrero | O14: No acreditado | P14: 010 / 914 800 010 (atencion municipal, no gestor directo) | R14: Concesión vigente; adjudicataria y fin 31/10/2028 contrastados en registro de concesiones municipal (15/10/2026). | FECHAS REVISADAS: Inicio 01/11/2022 acreditado por formalización de los cuatro lotes. | CONTROL DOCUMENTAL 21/10/2026: Adjudicación y fin publicados. Los cuatro lotes se pueden contrastar en el registro municipal de concesiones. Fin publicado: 31/10/2028. No generalizar ámbito de cada lote. [Base de evidencia: Portal municipal / resolución o resultado oficial consultado] | CONTRASTE ADICIONAL 21/10/2026: FUENTE MUNICIPAL: la concesión registra adjudicación diferenciada en los 4 lotes (FCC, UTE VAO, UTE Sur, CONTENUR) y fin contractual 31/10/2028. | S14: https://contratacion.madrid.es/concesiones/ https://contrataciondelestado.es/FileSystem/servlet/GetDocumentByIdServlet?DocumentIdParam=I52CDqtLbsdgHyWk6Tjc%2BH2t2QGKU1Ro9lcaZmb7V5J4T4CLRYtO18fD2fcADXQg90aL83OqQbUADSXvNu02Vt6kOzxNccJdTRf8umMgorI%3D&cifrado=QUC1GjXXSiLkydRHJBmbpw%3D%3D | T14: REL-0013 | U14: 131/2021/06296|2 | V14: =IF(AND(SUM(IF('Consulta de contratos'!$K$1="",0,1),IF('Consulta de contratos'!$K$2="",0,1),IF('Consulta de contratos'!$K$3="",0,1),IF('Consulta de contratos'!$K$4="",0,1),IF('Consulta de contratos'!$K$5="",0,1),IF('Consulta de contratos'!$K$6="",0,1))>0,OR('Consulta de contratos'!$K$1="",A14='Consulta de contratos'!$K$1),OR('Consulta de contratos'!$K$2="",I14='Consulta de contratos'!$K$2),OR('Consulta de contratos'!$K$3="",C14='Consulta de contratos'!$K$3),OR('Consulta de contratos'!$K$4="",D14='Consulta de contratos'!$K$4),OR('Consulta de contratos'!$K$5="",E14='Consulta de contratos'!$K$5),OR('Consulta de contratos'!$K$6="",IFERROR(ISNUMBER(SEARCH("|"&'Consulta de contratos'!$K$6&"|",AF14)),FALSE))),1,0) -> 0 | W14: =IF(V14=1,SUM($V$2:V14),0) -> 0 | X14: FIN REGISTRADO POSTERIOR · EJECUCIÓN A CONFIRMAR | Y14: ACCIONA | VALORIZA | OHL / INGESAN | Z14: UTE: vínculo comercial; no implica propiedad | AA14: 16/10/2026 | AF14: |ACCIONA|VALORIZA|OHL / INGESAN|
A15: Retiro | B15: Residuos | C15: Área de Gobierno de Urbanismo, Medio Ambiente y Movilidad | D15: Dirección General de Servicios de Limpieza y Residuos | E15: Subdirección General de Recogida de Residuos | F15: Contenerización, recogida y transporte de residuos | G15: 131/2021/06296 | H15: 4 | I15: CONTENUR SL | J15: Suministro, mantenimiento y limpieza de contenedores | K15: Toda la ciudad | L15: 44866 | M15: 47057 | N15: Víctor Manuel Sarabia Herrero | O15: No acreditado | P15: 010 / 914 800 010 (atencion municipal, no gestor directo) | Q15: No es vaciado ni recogida habitual | R15: Concesión vigente; adjudicataria y fin 31/10/2028 contrastados en registro de concesiones municipal (15/10/2026). | FECHAS REVISADAS: Inicio 01/11/2022 acreditado por formalización de los cuatro lotes. | CONTROL DOCUMENTAL 21/10/2026: Adjudicación y fin publicados. Los cuatro lotes se pueden contrastar en el registro municipal de concesiones. Fin publicado: 31/10/2028. No generalizar ámbito de cada lote. [Base de evidencia: Portal municipal / resolución o resultado oficial consultado] | CONTRASTE ADICIONAL 21/10/2026: FUENTE MUNICIPAL: la concesión registra adjudicación diferenciada en los 4 lotes (FCC, UTE VAO, UTE Sur, CONTENUR) y fin contractual 31/10/2028. | S15: https://contratacion.madrid.es/concesiones/ https://contrataciondelestado.es/FileSystem/servlet/GetDocumentByIdServlet?DocumentIdParam=I52CDqtLbsdgHyWk6Tjc%2BH2t2QGKU1Ro9lcaZmb7V5J4T4CLRYtO18fD2fcADXQg90aL83OqQbUADSXvNu02Vt6kOzxNccJdTRf8umMgorI%3D&cifrado=QUC1GjXXSiLkydRHJBmbpw%3D%3D | T15: REL-0014 | U15: 131/2021/06296|4 | V15: =IF(AND(SUM(IF('Consulta de contratos'!$K$1="",0,1),IF('Consulta de contratos'!$K$2="",0,1),IF('Consulta de contratos'!$K$3="",0,1),IF('Consulta de contratos'!$K$4="",0,1),IF('Consulta de contratos'!$K$5="",0,1),IF('Consulta de contratos'!$K$6="",0,1))>0,OR('Consulta de contratos'!$K$1="",A15='Consulta de contratos'!$K$1),OR('Consulta de contratos'!$K$2="",I15='Consulta de contratos'!$K$2),OR('Consulta de contratos'!$K$3="",C15='Consulta de contratos'!$K$3),OR('Consulta de contratos'!$K$4="",D15='Consulta de contratos'!$K$4),OR('Consulta de contratos'!$K$5="",E15='Consulta de contratos'!$K$5),OR('Consulta de contratos'!$K$6="",IFERROR(ISNUMBER(SEARCH("|"&'Consulta de contratos'!$K$6&"|",AF15)),FALSE))),1,0) -> 0 | W15: =IF(V15=1,SUM($V$2:V15),0) -> 0 | X15: FIN REGISTRADO POSTERIOR · EJECUCIÓN A CONFIRMAR | Y15: CONTENUR SL | Z15: Agrupación de consulta por nombre de adjudicataria; no consta matriz contrastada. | AA15: 16/10/2026 | AF15: |CONTENUR SL|
A16: Retiro | B16: Residuos | C16: Área de Gobierno de Urbanismo, Medio Ambiente y Movilidad | D16: Dirección General de Servicios de Limpieza y Residuos | E16: Subdirección General de Recogida de Residuos | F16: Contenerización, recogida y transporte de residuos | G16: 131/2021/06296 | H16: 3 | I16: UTE 2022 Recogida Madrid Sur | J16: Recogida de pilas y baterias usadas | K16: Toda la ciudad | L16: 44866 | M16: 47057 | N16: Víctor Manuel Sarabia Herrero | O16: No acreditado | P16: 010 / 914 800 010 (atencion municipal, no gestor directo) | Q16: Tarea especial del lote 3 fuera de su zona habitual | R16: Concesión vigente; adjudicataria y fin 31/10/2028 contrastados en registro de concesiones municipal (15/10/2026). | FECHAS REVISADAS: Inicio 01/11/2022 acreditado por formalización de los cuatro lotes. | CONTROL DOCUMENTAL 21/10/2026: Adjudicación y fin publicados. Los cuatro lotes se pueden contrastar en el registro municipal de concesiones. Fin publicado: 31/10/2028. No generalizar ámbito de cada lote. [Base de evidencia: Portal municipal / resolución o resultado oficial consultado] | CONTRASTE ADICIONAL 21/10/2026: FUENTE MUNICIPAL: la concesión registra adjudicación diferenciada en los 4 lotes (FCC, UTE VAO, UTE Sur, CONTENUR) y fin contractual 31/10/2028. | S16: https://contratacion.madrid.es/concesiones/ https://contrataciondelestado.es/FileSystem/servlet/GetDocumentByIdServlet?DocumentIdParam=I52CDqtLbsdgHyWk6Tjc%2BH2t2QGKU1Ro9lcaZmb7V5J4T4CLRYtO18fD2fcADXQg90aL83OqQbUADSXvNu02Vt6kOzxNccJdTRf8umMgorI%3D&cifrado=QUC1GjXXSiLkydRHJBmbpw%3D%3D | T16: REL-0015 | U16: 131/2021/06296|3 | V16: =IF(AND(SUM(IF('Consulta de contratos'!$K$1="",0,1),IF('Consulta de contratos'!$K$2="",0,1),IF('Consulta de contratos'!$K$3="",0,1),IF('Consulta de contratos'!$K$4="",0,1),IF('Consulta de contratos'!$K$5="",0,1),IF('Consulta de contratos'!$K$6="",0,1))>0,OR('Consulta de contratos'!$K$1="",A16='Consulta de contratos'!$K$1),OR('Consulta de contratos'!$K$2="",I16='Consulta de contratos'!$K$2),OR('Consulta de contratos'!$K$3="",C16='Consulta de contratos'!$K$3),OR('Consulta de contratos'!$K$4="",D16='Consulta de contratos'!$K$4),OR('Consulta de contratos'!$K$5="",E16='Consulta de contratos'!$K$5),OR('Consulta de contratos'!$K$6="",IFERROR(ISNUMBER(SEARCH("|"&'Consulta de contratos'!$K$6&"|",AF16)),FALSE))),1,0) -> 0 | W16: =IF(V16=1,SUM($V$2:V16),0) -> 0 | X16: FIN REGISTRADO POSTERIOR · EJECUCIÓN A CONFIRMAR | Y16: PREZERO | URBASER | Z16: UTE: vínculo comercial; no implica propiedad | AA16: 16/10/2026 | AF16: |PREZERO|URBASER|
A17: Retiro | B17: Residuos | C17: Área de Gobierno de Urbanismo, Medio Ambiente y Movilidad | D17: Dirección General de Servicios de Limpieza y Residuos | E17: Subdirección General de Recogida de Residuos | F17: Asistencia técnica para el mantenimiento, ampliación y mejora continua del sistema de gestión de la información de limpieza urbana, recogida de residuos y equipamientos urbanos | G17: 300/2025/00411 | H17: Sin lotes | I17: APORTA PLATAFORMA COOPERATIVA SCCL | J17: Mantenimiento y mejora del sistema de informacion | K17: Ambito municipal; no contrato propio del distrito | M17: 46850 | N17: Víctor Manuel Sarabia Herrero | O17: No acreditado | P17: 010 / 914 800 010 (atencion municipal, no gestor directo) | R17: Adjudicado 27/01/2026 y formalizado 08/04/2026. Fin publicado 07/04/2028 (posible prórroga 12 meses). Inicio de prestación no acreditado. | FECHAS SIN ACREDITAR: Formalización 08/04/2026 y fin en agregador 07/04/2028; no consta fecha independiente de inicio de prestación. La formalización no se convierte en inicio automático. | FUENTES REVISADAS 21/10/2026: Ayuntamiento publica objeto y pliegos; registro TED del contrato identifica formalización el 08/04/2026 y adjudicataria Aporta. No equivale a fecha de inicio operativo. | CONTROL DOCUMENTAL 21/10/2026: Adjudicataria identificada. APORTA PLATAFORMA COOPERATIVA figura en la base y en fichas de licitación; comprobar firma e hitos en el expediente. [Base de evidencia: Datos confrontados con referencias aportadas; no hay resolución individual corroborada] | CONTRASTE ADICIONAL 21/10/2026: ADJUDICACIÓN: APORTA PLATAFORMA COOPERATIVA SCCL, resolución de 27/01/2026, contrastada con publicación de licitación. | S17: https://contratos.gobierto.es/adjudicatarios/aporta-plataforma-cooperativa-sccl?locale=es https://www.madrid.es/portales/munimadrid/es/Inicio/Medio-ambiente/Limpieza-urbana/Contrato-de-servicio-de-asistencia-tecnica/?vgnextchannel=ddd2a694fde40910VgnVCM2000001f4a900aRCRD&vgnextfmt=default&vgnextoid=7c07475398a4e910VgnVCM200000f921e388RCRD https://contratos.gobierto.es/licitaciones/4668721?locale=es | T17: REL-0016 | U17: 300/2025/00411|Sin lotes | V17: =IF(AND(SUM(IF('Consulta de contratos'!$K$1="",0,1),IF('Consulta de contratos'!$K$2="",0,1),IF('Consulta de contratos'!$K$3="",0,1),IF('Consulta de contratos'!$K$4="",0,1),IF('Consulta de contratos'!$K$5="",0,1),IF('Consulta de contratos'!$K$6="",0,1))>0,OR('Consulta de contratos'!$K$1="",A17='Consulta de contratos'!$K$1),OR('Consulta de contratos'!$K$2="",I17='Consulta de contratos'!$K$2),OR('Consulta de contratos'!$K$3="",C17='Consulta de contratos'!$K$3),OR('Consulta de contratos'!$K$4="",D17='Consulta de contratos'!$K$4),OR('Consulta de contratos'!$K$5="",E17='Consulta de contratos'!$K$5),OR('Consulta de contratos'!$K$6="",IFERROR(ISNUMBER(SEARCH("|"&'Consulta de contratos'!$K$6&"|",AF17)),FALSE))),1,0) -> 0 | W17: =IF(V17=1,SUM($V$2:V17),0) -> 0 | X17: FIN REGISTRADO POSTERIOR · EJECUCIÓN A CONFIRMAR | Y17: APORTA PLATAFORMA COOPERATIVA SCCL | Z17: Agrupación de consulta por nombre de adjudicataria; no consta matriz contrastada. | AA17: 16/10/2026 | AF17: |APORTA PLATAFORMA COOPERATIVA SCCL|
